Workbook

Sheet Company Overview – BNPL Fintech
A1: Our company operates in the Buy Now Pay Later (BNPL) sector in the United Arab Emirates, targeting both individual users and partner merchants through a B2C and B2B2C model. We are currently raising a Seed+ round of USD 2.5M to accelerate growth, expand merchant integrations, and strengthen our risk-scoring infrastructure ahead of a future Series A.
A3: Market Context
A5: The UAE consumer finance market shows strong demand for flexible payment solutions, especially among young expatriates, who often face:
A7: Low access to traditional consumer credit
A9: High interest rates on small-ticket loans (< 5,000 AED)
A11: Growing reliance on e-commerce purchases requiring installment options
A13: This structural gap creates an opportunity for a scalable and compliant BNPL alternative.
A15: Problem
A17: Limited adoption of consumer credit due to strict banking requirements
A19: High APRs preventing small recurring purchases
A21: Merchants lacking simple installment tools for conversion and retention
A23: Solution
... A39: This model allows us to scale both digitally and through merchant networks, improving conversion rates while managing risk through proprietary scoring.

Sheet Historical_Data & Analysis
A1: Note: Some calculations such as LT, LTV, Take Rate, and Payback Period were performed using Power Query to streamline data processing. The remaining figures come from historical data.
A2: Mois | B2: New Users | C2: CAC | D2: Marketing Spend | E2: Paid Users | F2: Organic Users | G2: Active Users | H2: Churn % | I2: GMV | J2: BNPL Tx | K2: Revenue | L2: Merchant Fees | M2: Late Fees | N2: Interchange | O2: Cost of Funds | P2: Bad Debt | Q2: Salaries | R2: Tech & Cloud | S2: Compliance | T2: G&A | U2: ARPU | V2: GM % | W2: CM % | X2: LT | Y2: LTV | Z2: Take rate | AA2: Payback period
A3: 1 | B3: 950 | C3: 65 | D3: 62000 | E3: 670 | F3: 280 | G3: 950 | H3: 0.06 | I3: 1150000 | J3: 1050 | K3: 41000 | L3: 34000 | M3: 3800 | N3: 2800 | O3: 13000 | P3: 1200 | Q3: 38000 | R3: 9000 | S3: 5200 | T3: 7800 | U3: 43 | V3: 0.74 | W3: 0.63 | X3: 16.666667 | Y3: 530.33333 | Z3: 0.035652174 | AA3: 2.0427404
A4: 2 | B4: 1020 | C4: 60 | D4: 61000 | E4: 700 | F4: 320 | G4: 970 | H4: 0.055 | I4: 1220000 | J4: 1100 | K4: 43500 | L4: 36000 | M4: 4200 | N4: 3300 | O4: 12800 | P4: 1250 | Q4: 39000 | R4: 9200 | S4: 5100 | T4: 8000 | U4: 45 | V4: 0.75 | W4: 0.64 | X4: 18.181818 | Y4: 613.63636 | Z4: 0.035655738 | AA4: 1.7777778
A5: 3 | B5: 1080 | C5: 58 | D5: 63000 | E5: 730 | F5: 350 | G5: 1000 | H5: 0.052 | I5: 1290000 | J5: 1150 | K5: 45600 | L5: 37500 | M5: 4400 | N5: 3600 | O5: 12900 | P5: 1350 | Q5: 40000 | R5: 9500 | S5: 5000 | T5: 8300 | U5: 46 | V5: 0.75 | W5: 0.65 | X5: 19.230769 | Y5: 663.46154 | Z5: 0.035348837 | AA5: 1.6811594
A6: 4 | B6: 1120 | C6: 62 | D6: 70000 | E6: 750 | F6: 370 | G6: 1015 | H6: 0.058 | I6: 1315000 | J6: 1180 | K6: 47000 | L6: 38500 | M6: 4700 | N6: 3800 | O6: 13500 | P6: 1400 | Q6: 42000 | R6: 9800 | S6: 5400 | T6: 8600 | U6: 47 | V6: 0.74 | W6: 0.64 | X6: 17.241379 | Y6: 599.65517 | Z6: 0.035741445 | AA6: 1.7826337
A7: 5 | B7: 1250 | C7: 68 | D7: 85000 | E7: 820 | F7: 430 | G7: 1100 | H7: 0.065 | I7: 1500000 | J7: 1350 | K7: 52000 | L7: 43000 | M7: 5200 | N7: 4300 | O7: 14000 | P7: 2000 | Q7: 44000 | R7: 10500 | S7: 5600 | T7: 9200 | U7: 47 | V7: 0.73 | W7: 0.62 | X7: 15.384615 | Y7: 527.84615 | Z7: 0.034666667 | AA7: 1.9819295
A8: 6 | B8: 1180 | C8: 62 | D8: 73000 | E8: 780 | F8: 400 | G8: 1080 | H8: 0.056 | I8: 1450000 | J8: 1310 | K8: 50500 | L8: 42000 | M8: 5000 | N8: 3800 | O8: 13800 | P8: 1850 | Q8: 45000 | R8: 10600 | S8: 5500 | T8: 9000 | U8: 46 | V8: 0.75 | W8: 0.64 | X8: 17.857143 | Y8: 616.07143 | Z8: 0.034827586 | AA8: 1.7971014
A9: 7 | B9: 1300 | C9: 70 | D9: 91000 | E9: 870 | F9: 430 | G9: 1200 | H9: 0.068 | I9: 1600000 | J9: 1450 | K9: 56000 | L9: 46500 | M9: 5400 | N9: 4200 | O9: 15000 | P9: 2100 | Q9: 47000 | R9: 11200 | S9: 5800 | T9: 9300 | U9: 48 | V9: 0.72 | W9: 0.61 | X9: 14.705882 | Y9: 508.23529 | Z9: 0.035 | AA9: 2.025463
A10: 8 | B10: 1400 | C10: 68 | D10: 95000 | E10: 920 | F10: 480 | G10: 1250 | H10: 0.06 | I10: 1750000 | J10: 1580 | K10: 61000 | L10: 50000 | M10: 5800 | N10: 5200 | O10: 15500 | P10: 1950 | Q10: 49000 | R10: 12000 | S10: 6000 | T10: 9800 | U10: 49 | V10: 0.73 | W10: 0.62 | X10: 16.666667 | Y10: 596.16667 | Z10: 0.034857143 | AA10: 1.9010344
A11: 9 | B11: 1350 | C11: 75 | D11: 101000 | E11: 900 | F11: 450 | G11: 1230 | H11: 0.075 | I11: 1700000 | J11: 1520 | K11: 59500 | L11: 49000 | M11: 5700 | N11: 4800 | O11: 16000 | P11: 3200 | Q11: 51000 | R11: 12500 | S11: 6200 | T11: 9600 | U11: 48 | V11: 0.7 | W11: 0.59 | X11: 13.333333 | Y11: 448 | Z11: 0.035 | AA11: 2.2321429
A12: 10 | B12: 1500 | C12: 72 | D12: 108000 | E12: 1000 | F12: 500 | G12: 1300 | H12: 0.062 | I12: 1850000 | J12: 1700 | K12: 65000 | L12: 54000 | M12: 6000 | N12: 5000 | O12: 17000 | P12: 2300 | Q12: 54000 | R12: 13500 | S12: 6500 | T12: 10100 | U12: 50 | V12: 0.74 | W12: 0.64 | X12: 16.129032 | Y12: 596.77419 | Z12: 0.035135135 | AA12: 1.9459459
A13: 11 | B13: 1420 | C13: 70 | D13: 100000 | E13: 960 | F13: 460 | G13: 1280 | H13: 0.06 | I13: 1800000 | J13: 1660 | K13: 63200 | L13: 52500 | M13: 5900 | N13: 4800 | O13: 16800 | P13: 2100 | Q13: 56000 | R13: 13800 | S13: 6600 | T13: 10000 | U13: 49 | V13: 0.75 | W13: 0.65 | X13: 16.666667 | Y13: 612.5 | Z13: 0.035111111 | AA13: 1.9047619
A14: 12 | B14: 1600 | C14: 68 | D14: 110000 | E14: 1080 | F14: 520 | G14: 1400 | H14: 0.055 | I14: 1980000 | J14: 1850 | K14: 70000 | L14: 58000 | M14: 6300 | N14: 5900 | O14: 17500 | P14: 2400 | Q14: 58000 | R14: 14000 | S14: 6800 | T14: 10600 | U14: 52 | V14: 0.76 | W14: 0.66 | X14: 18.181818 | Y14: 718.54545 | Z14: 0.035353535 | AA14: 1.7206478
... A38: 36 | B38: 3350 | C38: 60 | D38: 190000 | E38: 2200 | F38: 1150 | G38: 2720 | H38: 0.035 | I38: 4900000 | J38: 4520 | K38: 175000 | L38: 146000 | M38: 14500 | N38: 9900 | O38: 24500 | P38: 3800 | Q38: 110000 | R38: 27500 | S38: 11500 | T38: 20000 | U38: 76 | V38: 0.83 | W38: 0.74 | X38: 28.571429 | Y38: 1802.2857 | Z38: 0.035714286 | AA38: 0.95117311

Sheet Cohort in value
A1: Cohort | B1: New users_start | C1: End M1 | D1: EndM2 | E1: M3 | F1: M4 | G1: M5 | H1: M6 | I1: M7 | J1: M8 | K1: M9 | L1: M10 | M1: M11 | N1: M12 | O1: M13 | P1: M14 | Q1: M15 | R1: M16 | S1: M17 | T1: M18 | U1: M19 | V1: M20 | W1: M21 | X1: M22 | Y1: M23 | Z1: M24 | AA1: M25 | AB1: M26 | AC1: M27 | AD1: M28 | AE1: M29 | AF1: M30 | AG1: M31 | AH1: M32 | AI1: M33 | AJ1: M34 | AK1: M35 | AL1: M36 | AM1: Churn mensuel
A2: 1 | B2: 950 | C2: 893 | D2: 839 | E2: 788 | F2: 740 | G2: 695 | H2: 653 | I2: 613 | J2: 576 | K2: 541 | L2: 508 | M2: 477 | N2: 448 | O2: 421 | P2: 395 | Q2: 371 | R2: 348 | S2: 327 | T2: 307 | U2: 288 | V2: 270 | W2: 253 | X2: 237 | Y2: 222 | Z2: 208 | AA2: 195 | AB2: 183 | AC2: 172 | AD2: 161 | AE2: 151 | AF2: 141 | AG2: 132 | AH2: 124 | AI2: 116 | AJ2: 109 | AK2: 102 | AL2: 95 | AM2: 0.06
A3: 2 | B3: 1020 | C3: 0 | D3: 958 | E3: 900 | F3: 846 | G3: 795 | H3: 747 | I3: 702 | J3: 659 | K3: 619 | L3: 581 | M3: 546 | N3: 513 | O3: 482 | P3: 453 | Q3: 425 | R3: 399 | S3: 375 | T3: 352 | U3: 330 | V3: 310 | W3: 291 | X3: 273 | Y3: 256 | Z3: 240 | AA3: 225 | AB3: 211 | AC3: 198 | AD3: 186 | AE3: 174 | AF3: 163 | AG3: 153 | AH3: 143 | AI3: 134 | AJ3: 125 | AK3: 117 | AL3: 109 | AM3: 0.0589
A4: 3 | B4: 1080 | C4: 0 | D4: 0 | E4: 1015 | F4: 954 | G4: 896 | H4: 842 | I4: 791 | J4: 743 | K4: 698 | L4: 656 | M4: 616 | N4: 579 | O4: 544 | P4: 511 | Q4: 480 | R4: 451 | S4: 423 | T4: 397 | U4: 373 | V4: 350 | W4: 329 | X4: 309 | Y4: 290 | Z4: 272 | AA4: 255 | AB4: 239 | AC4: 224 | AD4: 210 | AE4: 197 | AF4: 185 | AG4: 173 | AH4: 162 | AI4: 152 | AJ4: 142 | AK4: 133 | AL4: 125 | AM4: 0.0605
A5: 4 | B5: 1120 | C5: 0 | D5: 0 | E5: 0 | F5: 1052 | G5: 988 | H5: 928 | I5: 872 | J5: 819 | K5: 769 | L5: 722 | M5: 678 | N5: 637 | O5: 598 | P5: 562 | Q5: 528 | R5: 496 | S5: 466 | T5: 438 | U5: 411 | V5: 386 | W5: 362 | X5: 340 | Y5: 319 | Z5: 299 | AA5: 281 | AB5: 264 | AC5: 248 | AD5: 233 | AE5: 219 | AF5: 205 | AG5: 192 | AH5: 180 | AI5: 169 | AJ5: 158 | AK5: 148 | AL5: 139 | AM5: 0.0604
A6: 5 | B6: 1250 | C6: 0 | D6: 0 | E6: 0 | F6: 0 | G6: 1175 | H6: 1104 | I6: 1037 | J6: 974 | K6: 915 | L6: 860 | M6: 808 | N6: 759 | O6: 713 | P6: 670 | Q6: 629 | R6: 591 | S6: 555 | T6: 521 | U6: 489 | V6: 459 | W6: 431 | X6: 405 | Y6: 380 | Z6: 357 | AA6: 335 | AB6: 314 | AC6: 295 | AD6: 277 | AE6: 260 | AF6: 244 | AG6: 229 | AH6: 215 | AI6: 202 | AJ6: 189 | AK6: 177 | AL6: 166 | AM6: 0.0605
A7: 6 | B7: 1180 | C7: 0 | D7: 0 | E7: 0 | F7: 0 | G7: 0 | H7: 1109 | I7: 1042 | J7: 979 | K7: 920 | L7: 864 | M7: 812 | N7: 763 | O7: 717 | P7: 673 | Q7: 632 | R7: 594 | S7: 558 | T7: 524 | U7: 492 | V7: 462 | W7: 434 | X7: 407 | Y7: 382 | Z7: 359 | AA7: 337 | AB7: 316 | AC7: 297 | AD7: 279 | AE7: 262 | AF7: 246 | AG7: 231 | AH7: 217 | AI7: 203 | AJ7: 190 | AK7: 178 | AL7: 167 | AM7: 0.0604
A8: 7 | B8: 1300 | C8: 0 | D8: 0 | E8: 0 | F8: 0 | G8: 0 | H8: 0 | I8: 1222 | J8: 1148 | K8: 1079 | L8: 1014 | M8: 953 | N8: 895 | O8: 841 | P8: 790 | Q8: 742 | R8: 697 | S8: 655 | T8: 615 | U8: 578 | V8: 543 | W8: 510 | X8: 479 | Y8: 450 | Z8: 423 | AA8: 397 | AB8: 373 | AC8: 350 | AD8: 329 | AE8: 309 | AF8: 290 | AG8: 272 | AH8: 255 | AI8: 239 | AJ8: 224 | AK8: 210 | AL8: 197 | AM8: 0.0604
A9: 8 | B9: 1400 | C9: 0 | D9: 0 | E9: 0 | F9: 0 | G9: 0 | H9: 0 | I9: 0 | J9: 1316 | K9: 1237 | L9: 1162 | M9: 1092 | N9: 1026 | O9: 964 | P9: 906 | Q9: 851 | R9: 799 | S9: 751 | T9: 705 | U9: 662 | V9: 622 | W9: 584 | X9: 548 | Y9: 515 | Z9: 484 | AA9: 454 | AB9: 426 | AC9: 400 | AD9: 376 | AE9: 353 | AF9: 331 | AG9: 311 | AH9: 292 | AI9: 274 | AJ9: 257 | AK9: 241 | AL9: 226 | AM9: 0.0609
A10: 9 | B10: 1350 | C10: 0 | D10: 0 | E10: 0 | F10: 0 | G10: 0 | H10: 0 | I10: 0 | J10: 0 | K10: 1269 | L10: 1192 | M10: 1120 | N10: 1052 | O10: 988 | P10: 928 | Q10: 872 | R10: 819 | S10: 769 | T10: 722 | U10: 678 | V10: 637 | W10: 598 | X10: 562 | Y10: 528 | Z10: 496 | AA10: 466 | AB10: 438 | AC10: 411 | AD10: 386 | AE10: 362 | AF10: 340 | AG10: 319 | AH10: 299 | AI10: 281 | AJ10: 264 | AK10: 248 | AL10: 233 | AM10: 0.0607
A11: 10 | B11: 1500 | C11: 0 | D11: 0 | E11: 0 | F11: 0 | G11: 0 | H11: 0 | I11: 0 | J11: 0 | K11: 0 | L11: 1410 | M11: 1325 | N11: 1245 | O11: 1170 | P11: 1099 | Q11: 1033 | R11: 971 | S11: 912 | T11: 857 | U11: 805 | V11: 756 | W11: 710 | X11: 667 | Y11: 626 | Z11: 588 | AA11: 552 | AB11: 518 | AC11: 486 | AD11: 456 | AE11: 428 | AF11: 402 | AG11: 377 | AH11: 354 | AI11: 332 | AJ11: 312 | AK11: 293 | AL11: 275 | AM11: 0.0605
A12: 11 | B12: 1420 | C12: 0 | D12: 0 | E12: 0 | F12: 0 | G12: 0 | H12: 0 | I12: 0 | J12: 0 | K12: 0 | L12: 0 | M12: 1334 | N12: 1253 | O12: 1177 | P12: 1106 | Q12: 1039 | R12: 976 | S12: 917 | T12: 861 | U12: 809 | V12: 760 | W12: 714 | X12: 671 | Y12: 630 | Z12: 592 | AA12: 556 | AB12: 522 | AC12: 490 | AD12: 460 | AE12: 432 | AF12: 406 | AG12: 381 | AH12: 358 | AI12: 336 | AJ12: 315 | AK12: 296 | AL12: 278 | AM12: 0.0603
A13: 12 | B13: 1600 | C13: 0 | D13: 0 | E13: 0 | F13: 0 | G13: 0 | H13: 0 | I13: 0 | J13: 0 | K13: 0 | L13: 0 | M13: 0 | N13: 1504 | O13: 1413 | P13: 1328 | Q13: 1248 | R13: 1173 | S13: 1102 | T13: 1035 | U13: 972 | V13: 913 | W13: 858 | X13: 806 | Y13: 757 | Z13: 711 | AA13: 668 | AB13: 627 | AC13: 589 | AD13: 553 | AE13: 519 | AF13: 487 | AG13: 457 | AH13: 429 | AI13: 403 | AJ13: 378 | AK13: 355 | AL13: 333 | AM13: 0.0605
... A37: 36 | B37: 3350 | C37: 0 | D37: 0 | E37: 0 | F37: 0 | G37: 0 | H37: 0 | I37: 0 | J37: 0 | K37: 0 | L37: 0 | M37: 0 | N37: 0 | O37: 0 | P37: 0 | Q37: 0 | R37: 0 | S37: 0 | T37: 0 | U37: 0 | V37: 0 | W37: 0 | X37: 0 | Y37: 0 | Z37: 0 | AA37: 0 | AB37: 0 | AC37: 0 | AD37: 0 | AE37: 0 | AF37: 0 | AG37: 0 | AH37: 0 | AI37: 0 | AJ37: 0 | AK37: 0 | AL37: 3149 | AM37: 0.0512

Sheet Analysis
A3: Cohort Analysis | G3: Metrics
A4: Cohorte | B4: New users_start | C4: Rétention End A1 (M12) | D4: Rétention End A2 (M24) | E4: Rétention End A3 (M36) | H4: 2022 | I4: 2023 | J4: 2024 | K4: Trend | L4: Note
A5: 1 | B5: 950 | C5: 0.502 | D5: 0.234 | E5: 0.1 | G5: Gross margin | H5: =AVERAGE('Historical_Data & Analysis'!V3:V13) -> 0.73636364 | I5: =AVERAGE('Historical_Data & Analysis'!V14:V25) -> 0.75916667 | J5: =AVERAGE('Historical_Data & Analysis'!V26:V38) -> 0.78769231 | L5: Method Used : Arythmetic average based on monthly data
A6: 2 | B6: 1020 | C6: 0.503 | D6: 0.251 | E6: 0.107 | G6: CAC | H6: =AVERAGE('Historical_Data & Analysis'!C3:C14) -> 66.5 | I6: =AVERAGE('Historical_Data & Analysis'!C15:C26) -> 68.333333 | J6: =AVERAGE('Historical_Data & Analysis'!C27:C38) -> 65.25
A7: 3 | B7: 1080 | C7: 0.536 | D7: 0.269 | E7: 0.116 | G7: LT | H7: =AVERAGE('Historical_Data & Analysis'!X3:X13) -> 16.55127 | I7: =AVERAGE('Historical_Data & Analysis'!X14:X25) -> 18.150024 | J7: =AVERAGE('Historical_Data & Analysis'!X26:X38) -> 21.623692
A8: 4 | B8: 1120 | C8: 0.569 | D8: 0.285 | E8: 0.124 | G8: LTV | H8: =AVERAGE('Historical_Data & Analysis'!Y3:Y13) -> 573.88001 | I8: =AVERAGE('Historical_Data & Analysis'!Y14:Y25) -> 790.13353 | J8: =AVERAGE('Historical_Data & Analysis'!Y26:Y38) -> 1175.8723
A9: 5 | B9: 1250 | C9: 0.607 | D9: 0.304 | E9: 0.133 | G9: Take rate | H9: =AVERAGE('Historical_Data & Analysis'!Z3:Z13) -> 0.03518144 | I9: =AVERAGE('Historical_Data & Analysis'!Z14:Z25) -> 0.035517248 | J9: =AVERAGE('Historical_Data & Analysis'!Z26:Z38) -> 0.035622587
A10: 6 | B10: 1180 | C10: 0.647 | D10: 0.324 | E10: 0.142 | G10: Payback period | H10: =AVERAGE('Historical_Data & Analysis'!AA3:AA13) -> 1.9156991 | I10: =AVERAGE('Historical_Data & Analysis'!AA14:AA25) -> 1.5862179 | J10: =AVERAGE('Historical_Data & Analysis'!AA26:AA38) -> 1.2327317
A11: 7 | B11: 1300 | C11: 0.688 | D11: 0.346 | E11: 0.152 | G11: CMGR | H11: =((Table[[#This Row],[Revenue]]-'Historical_Data & Analysis'!K3)^(1/12))-1 -> 1.2677629 | I11: =(('Historical_Data & Analysis'!K26-'Historical_Data & Analysis'!K15)^(1/12))-1 -> 1.4182712 | J11: =(('Historical_Data & Analysis'!K38-'Historical_Data & Analysis'!K27)^(1/12))-1 -> 1.4870375
A12: 8 | B12: 1400 | C12: 0.733 | D12: 0.368 | E12: 0.161 | G12: LTV/CAC | H12: =H8/H6 -> 8.6297746 | I12: =I8/I6 -> 11.56293 | J12: =J8/J6 -> 18.021032
A13: 9 | B13: 1350 | C13: 0.78 | D13: 0.391 | E13: 0.173
A14: 10 | B14: 1500 | C14: 0.83 | D14: 0.418 | E14: 0.183
A15: 11 | B15: 1420 | C15: 0.882 | D15: 0.441 | E15: 0.196
A16: 12 | B16: 1600 | C16: 0.94 | D16: 0.473 | E16: 0.208
A17: 13 | B17: 1700 | C17: - | D17: 0.474 | E17: 0.222
A18: 14 | B18: 1620 | C18: - | D18: 0.504 | E18: 0.252
A19: 15 | B19: 1750 | C19: - | D19: 0.538 | E19: 0.253
A20: 16 | B20: 1800 | C20: - | D20: 0.572 | E20: 0.27
A21: 17 | B21: 1850 | C21: - | D21: 0.608 | E21: 0.287
A22: 18 | B22: 1780 | C22: - | D22: 0.646 | E22: 0.306
A23: 19 | B23: 1900 | C23: - | D23: 0.691 | E23: 0.326
A24: 20 | B24: 2000 | C24: - | D24: 0.733 | E24: 0.347
A25: 21 | B25: 2100 | C25: - | D25: 0.78 | E25: 0.369
A26: 22 | B26: 2050 | C26: - | D26: 0.83 | E26: 0.393
A27: 23 | B27: 2200 | C27: - | D27: 0.883 | E27: 0.419
A28: 24 | B28: 2300 | C28: - | D28: 0.94 | E28: 0.446
A29: 25 | B29: 2400 | C29: - | D29: - | E29: 0.474
A30: 26 | B30: 2350 | C30: - | D30: - | E30: 0.505
A31: 27 | B31: 2500 | C31: - | D31: - | E31: 0.537
A32: 28 | B32: 2600 | C32: - | D32: - | E32: 0.572
A33: 29 | B33: 2550 | C33: - | D33: - | E33: 0.608
A34: 30 | B34: 2700 | C34: - | D34: - | E34: 0.647
A35: 31 | B35: 2800 | C35: - | D35: - | E35: 0.689
A36: 32 | B36: 2950 | C36: - | D36: - | E36: 0.733
A37: 33 | B37: 3000 | C37: - | D37: - | E37: 0.78
A38: 34 | B38: 3100 | C38: - | D38: - | E38: 0.83
A39: 35 | B39: 3200 | C39: - | D39: - | E39: 0.883
A40: 36 | B40: 3350 | C40: - | D40: - | E40: 0.94

Sheet P&L Forecast
A1: Projected P&L | J1: Drivers
B2: 2024A | C2: 2025E | D2: 2026E | E2: 2027E | F2: 2028E | G2: 2029E | J2: New Users
A3: Revenue | B3: =SUM(B4:B6) -> 1648800 | C3: =SUM(C4:C6) -> 4822187.3 | D3: =SUM(D4:D6) -> 8119527.9 | E3: =SUM(E4:E6) -> 18666348 | F3: =SUM(F4:F6) -> 31819427 | G3: =SUM(G4:G6) -> 41905423 | J3: New Users(t) = New Users(t–1) × (1 + growth rate)
A4: Merchant fees | B4: =SUM('Historical_Data & Analysis'!L27:L38) -> 1396000 | C4: =SUM(L38:W38) -> 4267422.4 | D4: =B25*B61 -> 7201355.1 | E4: =D25*C61 -> 16555519 | F4: =F25*D61 -> 28221221 | G4: =H25*E61 -> 36946777
A5: Late fees | B5: =SUM('Historical_Data & Analysis'!M27:M38) -> 140400 | C5: =SUM(L39:W39) -> 320056.68 | D5: =B25*B39 -> 540101.63 | E5: =D25*C62 -> 1241663.9 | F5: =F25*D62 -> 2116591.6 | G5: =H25*E62 -> 2916850.8 | J5: Active Customers
A6: Interchange | B6: =SUM('Historical_Data & Analysis'!N27:N38) -> 112400 | C6: =SUM(L40:W40) -> 234708.23 | D6: =B25*B63 -> 378071.14 | E6: =D25*C63 -> 869164.75 | F6: =F25*D63 -> 1481614.1 | G6: =H25*E63 -> 2041795.6 | J6: Active Users = Previous Active + (New × Stickiness) – Churned
A7: COGS | B7: =SUM(B8:B9) -> 313500 | C7: =SUM(C8:C9) -> 618776.25 | D7: =SUM(D8:D9) -> 1026193.1 | E7: =SUM(E8:E9) -> 3021382.2 | F7: =SUM(F8:F9) -> 6420327.8 | G7: =SUM(G8:G9) -> 9431151
A8: Cost of funds | B8: =SUM('Historical_Data & Analysis'!O27:O38) -> 273000 | C8: =SUM(L42:W42) -> 533427.8 | D8: =(B54*B25)*B55 -> 900169.39 | E8: =(D25*C54)*C55 -> 2731660.6 | F8: =(D54*F25)*D55 -> 5926456.4 | G8: =(H25*E54)*E55 -> 8847780.8 | J8: GMV
A9: Bad debt | B9: =SUM('Historical_Data & Analysis'!P27:P38) -> 40500 | C9: =SUM(L43:W43) -> 85348.449 | D9: =B25*B56 -> 126023.71 | E9: =C56*D25 -> 289721.58 | F9: =F25*D56 -> 493871.37 | G9: =E56*H25 -> 583370.16 | J9: GMV = Active Users × Average Transaction Amount
A10: Gross margin | B10: =(B3-B7)/B3 -> 0.80986172 | C10: =(C3-C7)/C3 -> 0.87168142 | D10: =(D3-D7)/D3 -> 0.87361419 | E10: =(E3-E7)/E3 -> 0.83813747 | F10: =(F3-F7)/F3 -> 0.79822616 | G10: =(G3-G7)/G3 -> 0.774942
A11: OPEX | B11: =SUM(B12:B16) -> 3857600 | C11: =SUM(C12:C16) -> 7764206.2 | D11: =SUM(D12:D16) -> 12905315 | E11: =SUM(E12:E16) -> 22020150 | F11: =SUM(F12:F16) -> 30744017 | G11: =SUM(G12:G16) -> 34812143 | J11: Revenue
A12: Marketing | B12: 2099000 | C12: =SUM(L49:W49) -> 3664493.4 | D12: =B22*B67 -> 4675786.6 | E12: =D22*C67 -> 5131451.4 | F12: =F22*D67 -> 5593264.7 | G12: =H22*E67 -> 5723848.2 | J12: Merchant fees = GMV × %
A13: Compliance | B13: =SUM('Historical_Data & Analysis'!S27:S38) -> 123700 | C13: =SUM(L50:W50) -> 266713.9 | D13: =B25*B60 -> 396074.53 | E13: =D25*C60 -> 827775.95 | F13: =F25*D60 -> 1411061 | G13: =H25*E60 -> 1555653.8 | J13: Late fees = GMV × %
A14: Salaries | B14: =SUM('Historical_Data & Analysis'!Q27:Q38) -> 1144000 | C14: =SUM(L51:W51) -> 2555759.3 | D14: =D3*B57 -> 4059763.9 | E14: =E3*C57 -> 8399856.5 | F14: =F3*D57 -> 12727771 | G14: =G3*E57 -> 14666898 | J14: Interchange = GMV × %
A15: G&A | B15: =SUM('Historical_Data & Analysis'!T27:T38) -> 204900 | C15: =C3*B35 -> 530440.61 | D15: =D3*B58 -> 893148.06 | E15: =E3*C58 -> 1866634.8 | F15: =F3*D58 -> 2545554.1 | G15: =G3*E58 -> 3142906.8 | J15: Revenue = sum of all components
A16: Tech & cloud | B16: =SUM('Historical_Data & Analysis'!R27:R38) -> 286000 | C16: =SUM(L44:W44) -> 746798.92 | D16: =B25*B59 -> 2880542 | E16: =D25*C59 -> 5794431.7 | F16: =F25*D59 -> 8466366.3 | G16: =H25*E59 -> 9722836
A17: EBITDA | B17: =B3-B7-B11 -> -2522300 | C17: =C3-C7-C11 -> -3560795.1 | D17: =D3-D7-D11 -> -5811980.4 | E17: =E3-E7-E11 -> -6375184.8 | F17: =F3-F7-F11 -> -5344918 | G17: =G3-G7-G11 -> -2337870.6 | J17: COGS
J18: Cost of funds = BNPL volume × factor
J19: Bad debt = GMV × %
J20: COGS = cost of funds + bad debt
A21: Core Business Drivers – Annual View | B21: 2026 | C21: 46082 | D21: 2027 | E21: 46447 | F21: 2028 | G21: 46813 | H21: 2029
A22: New user | B22: =W30*(((1+B52)^12-1)/(B52)) -> 71935.179 | C22: =W30*(1+B52)^11 -> 6668.7858 | D22: =C22*(((1+C52)^12-1)/(C52)) -> 85524.19 | E22: =C22*(1+C52)^11 -> 7603.8301 | F22: =E22*(((1+D52)^12-1)/(D52)) -> 96435.598 | G22: =E22*(1+D52)^11 -> 8483.3526 | H22: =G22*(((1+E52)^12-1)/(E52)) -> 104069.97 | J22: OPEX
A23: Nouveaux clients Actifs | B23: =B22*B53 -> 10070.925 | D23: =D22*C53 -> 12828.629 | F23: =F22*D53 -> 15911.874 | H23: =H22*E53 -> 17691.895 | J23: Salaries = Revenue × %
A24: Active users | B24: =(B23 / B64) + (W32 - (B23 / B64)) * (1 - B64)^12 -> 93687.774 | D24: =(D23 / C64) + (W32 - (D23 / C64)) * (1 - C64)^24 -> 202870.43 | F24: =(F23 / D64) + (W32 - (F23 / D64)) * (1 - D64)^36 -> 325730.94 | H24: =(H23 / E64) + (W32 - (H23 / E64)) * (1 - E64)^48 -> 438251.6 | J24: G&A = Revenue × %
A25: GMV | B25: =B51*B24 -> 1.8003388e+08 | D25: =D24*C51 -> 4.1388798e+08 | F25: =F24*D51 -> 7.0553052e+08 | H25: =H24*E51 -> 9.722836e+08 | J25: Tech & cloud = GMV × %
J26: Compliance = GMV × %
J27: Marketing = CAC × Paid share × New Users
A28: Monthly Assumptions | B28: 2025E | C28: Comment
A29: Average transaction amount per user | B29: 1810 | C29: Each month | J29: P&L 2025 per month | L29: M1 | M29: M2 | N29: M3 | O29: M4 | P29: M5 | Q29: M6 | R29: M7 | S29: M8 | T29: M9 | U29: M10 | V29: M11 | W29: M12
A30: Stickiness | B30: 0.13 | C30: of New users | J30: Growth Monthly new user | L30: =(1+$B$41)*'Historical_Data & Analysis'!B38 -> 3484 | M30: =(1+$B$38)*L30 -> 3623.36 | N30: =(1+$B$38)*M30 -> 3768.2944 | O30: =(1+$B$38)*N30 -> 3919.0262 | P30: =(1+$B$38)*O30 -> 4075.7872 | Q30: =(1+$B$38)*P30 -> 4238.8187 | R30: =(1+$B$38)*Q30 -> 4408.3715 | S30: =(1+$B$38)*R30 -> 4584.7063 | T30: =(1+$B$38)*S30 -> 4768.0946 | ... W30: =(1+$B$38)*V30 -> 5363.4579
A31: BNLP tx | B31: 0.001 | C31: of GMV | J31: Nouveaux clients Actifs | L31: =L30*$B$30 -> 452.92 | M31: =M30*$B$30 -> 471.0368 | N31: =N30*$B$30 -> 489.87827 | O31: =O30*$B$30 -> 509.4734 | P31: =P30*$B$30 -> 529.85234 | Q31: =Q30*$B$30 -> 551.04643 | R31: =R30*$B$30 -> 573.08829 | S31: =S30*$B$30 -> 596.01182 | ... W31: =W30*$B$30 -> 697.24953
A32: Factor cost of funds | B32: 5 | C32: of BNLP tx | J32: Active users | L32: =('Historical_Data & Analysis'!G38*(1-B43))+L31 -> 3036.92 | M32: =(L32*(1-$B$43))+M31 -> 3356.1108 | N32: =(M32*(1-$B$43))+N31 -> 3678.1835 | O32: =(N32*(1-$B$43))+O31 -> 4003.7478 | P32: =(O32*(1-$B$43))+P31 -> 4333.4127 | Q32: =(P32*(1-$B$43))+Q31 -> 4667.7885 | R32: =(Q32*(1-$B$43))+R31 -> 5007.4874 | S32: =(R32*(1-$B$43))+S31 -> 5353.1248 | T32: =(S32*(1-$B$43))+T31 -> 5705.3209 | ... W32: =(V32*(1-$B$43))+W31 -> 6807.553
A33: Bad debt | B33: 0.0008 | C33: of GMV | J33: GMV | L33: =B29*L32 -> 5496825.2 | M33: =($B$29*((1+0.5%)^(1)))*M32 -> 6104933.4 | N33: =($B$29*((1+0.5%)^(2)))*N32 -> 6724253.8 | O33: =($B$29*((1+0.5%)^(3)))*O32 -> 7356029.6 | P33: =($B$29*((1+0.5%)^(4)))*P32 -> 8001527 | Q33: =($B$29*((1+0.5%)^(5)))*Q32 -> 8662037.4 | R33: =($B$29*((1+0.5%)^(1)))*R32 -> 9108869.9 | S33: =($B$29*((1+0.5%)^(1)))*S32 -> 9737601.7 | T33: =($B$29*((1+0.5%)^(1)))*T32 -> 10378264 | U33: =($B$29*((1+0.5%)^(1)))*U32 -> 11031995 | V33: =($B$29*((1+0.5%)^(1)))*V32 -> 11699945 | W33: =($B$29*((1+0.5%)^(1)))*W32 -> 12383279
A34: Salaries | B34: 0.53 | C34: Of revenue
A35: G&A | B35: 0.11 | C35: of revenue | K35: M0 | L35: M1 | M35: M2 | N35: M3 | O35: M4 | P35: M5 | Q35: M6 | R35: M7 | S35: M8 | T35: M9 | U35: M10 | V35: M11 | W35: M12
A36: Tech & cloud | B36: 0.007 | C36: of GMV
A37: Compliance | B37: 0.0025 | C37: of GMV | J37: Revenue | K37: =SUM(K38:K40) -> 170400 | L37: =SUM(L38:L40) -> 248456.5 | M37: =SUM(M38:M40) -> 275942.99 | N37: =SUM(N38:N40) -> 303936.27 | O37: =SUM(O38:O40) -> 332492.54 | P37: =SUM(P38:P40) -> 361669.02 | Q37: =SUM(Q38:Q40) -> 391524.09 | R37: =SUM(R38:R40) -> 411720.92 | ... W37: =SUM(W38:W40) -> 559724.22
A38: Merchant fees | B38: 0.04 | C38: Fix fees | J38: Merchant fees | K38: ='Historical_Data & Analysis'!L38 -> 146000 | L38: =L33*$B$38 -> 219873.01 | M38: =M33*$B$38 -> 244197.33 | N38: =N33*$B$38 -> 268970.15 | O38: =O33*$B$38 -> 294241.18 | P38: =P33*$B$38 -> 320061.08 | Q38: =Q33*$B$38 -> 346481.5 | R38: =R33*$B$38 -> 364354.8 | S38: =S33*$B$38 -> 389504.07 | ... W38: =W33*$B$38 -> 495331.17
A39: Late fees | B39: 0.003 | C39: Of GMV | J39: Late fees | K39: ='Historical_Data & Analysis'!M38 -> 14500 | L39: =L33*$B$39 -> 16490.476 | M39: =M33*$B$39 -> 18314.8 | N39: =N33*$B$39 -> 20172.761 | O39: =O33*$B$39 -> 22068.089 | P39: =P33*$B$39 -> 24004.581 | Q39: =Q33*$B$39 -> 25986.112 | R39: =R33*$B$39 -> 27326.61 | S39: =S33*$B$39 -> 29212.805 | ... W39: =W33*$B$39 -> 37149.838
A40: Interchange fees | B40: 0.0022 | C40: Fixed charge given | J40: Interchange | K40: ='Historical_Data & Analysis'!N38 -> 9900 | L40: =L33*$B$40 -> 12093.015 | M40: =M33*$B$40 -> 13430.853 | N40: =N33*$B$40 -> 14793.358 | O40: =O33*$B$40 -> 16183.265 | P40: =P33*$B$40 -> 17603.359 | Q40: =Q33*$B$40 -> 19056.482 | R40: =R33*$B$40 -> 20039.514 | S40: =S33*$B$40 -> 21422.724 | ... W40: =W33*$B$40 -> 27243.214
...

Sheet Bridge
A1: GMV Bridge (2025 → 2029)
A2: Between 2025 and 2026, GMV increases mainly due to higher new-user volumes, improving stickiness, and a higher average transaction amount. Overall, GMV grows by approximately +88M, driven mostly by user growth (+72M) and an uplift in ARPU (+15M).
A3: From 2026 to 2027, GMV rises by about +234M, explained by strong expansion in active users, an increase in stickiness from 14% to 15%, and a 6% rise in the average transaction value. Roughly +168M comes from user volume, while +65M is explained by higher ARPU.
A4: From 2027 to 2028, GMV grows by about +292M. This is supported by continued scale in the active-user base, stickiness increasing to 16.5%, and a higher share of BNPL-eligible transactions. Around +210M comes from volume growth and +81M from ARPU gains.
A5: From 2028 to 2029, GMV increases by roughly +267M. The growth is slower but still material, driven by steady new-user acquisition, stickiness improving to 17%, and a slightly higher transaction value. About +204M comes from user volume and +62M from ARPU.
A7: Revenue Bridge (2025 → 2029)
A8: From 2025 to 2026, revenue increases by roughly +3.3M, driven by higher GMV flowing through merchant fees, late fees, and interchange.
A9: Between 2026 and 2027, revenue rises by approximately +10.5M, almost entirely explained by the sharp GMV expansion.
A10: From 2027 to 2028, revenue grows by around +13.1M, supported by GMV growth of +292M, stable fee rates, and higher late-fee income.
A11: Between 2028 and 2029, revenue increases by +10.1M. GMV keeps scaling, although the merchant-fee rate drops slightly from 4% to 3.8%, resulting in slower revenue growth relative to GMV.
A13: EBITDA Bridge (2025 → 2029)
A14: From 2025 to 2026, EBITDA declines by roughly –2.25M. Revenue grows significantly, but this is offset by higher salary expenses, an increase in tech and cloud costs indexed to GMV, and overall OPEX growing faster than revenue.
... A17: Between 2028 and 2029, EBITDA improves by around +2.3M. Revenue grows by +10M, but this is partially offset by a higher cost-of-funds factor (moving from 6 to 7) and higher financing costs. EBITDA remains negative but moves closer to break-even.

Sheet Valuation
A3: VC Method ARR
A5: Exit Multiple Comparable
A6: Afterpay | B6: Acquired by Block for ~25× revenue
A7: Tabby | B7: Revenue multiple estimated between 10× and 15×
A8: Tamara | B8: Similar revenue multiple range: 8× – 12×
A10: Based on market comparables and the start-up's growth, the exit multiple is estimated at 10
A12: VC Calculation
B13: 2025 | C13: 2026 | D13: 2027 | E13: 2028 | F13: 2029 | G13: 2030 | H13: 2031 | I13: 2032
A15: Revenue | B15: ='P&L Forecast'!C3 -> 4822187.3 | C15: ='P&L Forecast'!D3 -> 8119527.9 | D15: ='P&L Forecast'!E3 -> 18666348 | E15: ='P&L Forecast'!F3 -> 31819427 | F15: ='P&L Forecast'!G3 -> 41905423 | G15: =F15*(1+3%) -> 43162586 | H15: =G15*(1+3%) -> 44457464 | I15: =H15*(1+3%) -> 45791188
A16: Exit multiple | I16: 10
A17: Cash in year | I17: 7
A18: Post money future | I18: =I15*I16 -> 4.5791188e+08
A19: TIR | I19: 0.5
A20: Valorisation post money | I20: =(I16*I15)/((1+I19)^I17) -> 26800512
A21: Dilution | I21: =2500000/I20 -> 0.0932818
A23: Sensitivity Analysis VPM
C25: Multiple income scenarios
B26: =I20 -> 26800512 | C26: 5 | D26: =I16 -> 10 | E26: 12 | F26: 14 | G26: 16
A27: VC ownership scenarios (%) | B27: 0.3 | C27: 36487864 | D27: 36487864 | E27: 87570874 | F27: 1.0216602e+08 | G27: 1.1676117e+08
B28: 0.4 | C28: 21719792 | D28: 21719792 | E28: 52127501 | F28: 60815417 | G28: 69503334
B29: 0.5 | C29: 13400256 | D29: 13400256 | E29: 32160615 | F29: 37520717 | G29: 42880819
B30: 0.7 | C30: 5579682.2 | D30: 5579682.2 | E30: 13391237 | F30: 15623110 | G30: 17854983
B31: 0.8 | C31: 3739765.5 | D31: 3739765.5 | E31: 8975437.3 | F31: 10471344 | G31: 11967250
B32: 0.9 | C32: 2561395.9 | D32: 2561395.9 | E32: 6147350.1 | F32: 7171908.4 | G32: 8196466.8
A36: Score card Valuation
A38: Benchmark
A39: Tabby (UAE – BNPL) | B39: Seed valuation estimated between $15M and $25M
B40: (based on disclosed fundraising amounts and inferred dilution).
A42: Tamara (KSA – BNPL) | B42: Seed stage valuation estimated around $15M.
A44: Postpay (UAE – BNPL) | B44: Early-stage valuation estimated around $10M–$12M.
A46: Other Lending & Payments Fintechs (UAE) | B46: Typical Seed valuations range $12M–$20M depending on traction, GMV, risk profile, and partnerships.
A48: Base Assumption
A49: Average pre-money valuation of a comparable company in the region | B49: 12000000
A51: Comparison Factor | B51: Range | C51: Our start up | D51: Factor
A52: Strength of the Team | B52: 0.3 | C52: 1.3 | D52: =C52*B52 -> 0.39
A53: Size of the Opportunity | B53: 0.2 | C53: 1.4 | D53: =C53*B53 -> 0.28
A54: Product & Technology | B54: 0.15 | C54: 0.9 | D54: =C54*B54 -> 0.135
A55: Traction | B55: 0.1 | C55: 1 | D55: =C55*B55 -> 0.1
A56: Competitive Environment | B56: 0.1 | C56: 0.8 | D56: =C56*B56 -> 0.08 | G56: Score Card Valuation | I56: =B49*D59 -> 13440000
A57: Business Model / Unit Economics | B57: 0.15 | C57: 0.9 | D57: =C57*B57 -> 0.135
...
